<?xml version="1.0"?>
<sdf version="1.6">
  <model name="person_with_apriltag">
    <pose>-5 7 0 0 0 0</pose>

    <!-- Main body (person-sized box) -->
    <link name="base_link">
      <inertial>
        <mass>50.0</mass>
        <inertia>
          <ixx>3.33</ixx>
          <iyy>3.33</iyy>
          <izz>0.67</izz>
        </inertia>
      </inertial>

      <!-- Body collision -->
      <collision name="body_collision">
        <pose>0 0 0.75 0 0 0</pose>
        <geometry>
          <box>
            <size>0.4 0.4 1.5</size>
          </box>
        </geometry>
      </collision>

      <!-- Body visual (simple person shape) -->
      <visual name="body_visual">
        <pose>0 0 0.75 0 0 0</pose>
        <geometry>
          <box>
            <size>0.4 0.4 1.5</size>
          </box>
        </geometry>
        <material>
          <ambient>0.3 0.3 0.8 1</ambient>
          <diffuse>0.3 0.3 0.8 1</diffuse>
        </material>
      </visual>

      <!-- AprilTag on the back -->
      <visual name="apriltag_board">
        <pose>-0.21 0 1.2 0 1.5708 0</pose>  <!-- On back, standing upright -->
        <geometry>
          <box>
            <size>0.4 0.4 0.02</size>
          </box>
        </geometry>
        <material>
          <ambient>1 1 1 1</ambient>
          <diffuse>1 1 1 1</diffuse>
        </material>
      </visual>

      <!-- Black AprilTag pattern -->
      <visual name="apriltag_pattern">
        <pose>-0.22 0 1.2 0 1.5708 0</pose>
        <geometry>
          <box>
            <size>0.25 0.25 0.01</size>
          </box>
        </geometry>
        <material>
          <ambient>0 0 0 1</ambient>
          <diffuse>0 0 0 1</diffuse>
        </material>
      </visual>

      <!-- Green indicator center -->
      <visual name="apriltag_indicator">
        <pose>-0.23 0 1.2 0 1.5708 0</pose>
        <geometry>
          <box>
            <size>0.1 0.1 0.005</size>
          </box>
        </geometry>
        <material>
          <ambient>0 1 0 1</ambient>
          <diffuse>0 1 0 1</diffuse>
          <emissive>0 0.5 0 1</emissive>
        </material>
      </visual>
    </link>

    <!-- Left wheel -->
    <link name="left_wheel">
      <pose>0 0.25 0.1 1.5708 0 0</pose>
      <inertial>
        <mass>2.0</mass>
        <inertia>
          <ixx>0.01</ixx>
          <iyy>0.01</iyy>
          <izz>0.01</izz>
        </inertia>
      </inertial>
      <collision name="collision">
        <geometry>
          <cylinder>
            <radius>0.1</radius>
            <length>0.05</length>
          </cylinder>
        </geometry>
      </collision>
      <visual name="visual">
        <geometry>
          <cylinder>
            <radius>0.1</radius>
            <length>0.05</length>
          </cylinder>
        </geometry>
        <material>
          <ambient>0.2 0.2 0.2 1</ambient>
          <diffuse>0.2 0.2 0.2 1</diffuse>
        </material>
      </visual>
    </link>

    <!-- Right wheel -->
    <link name="right_wheel">
      <pose>0 -0.25 0.1 1.5708 0 0</pose>
      <inertial>
        <mass>2.0</mass>
        <inertia>
          <ixx>0.01</ixx>
          <iyy>0.01</iyy>
          <izz>0.01</izz>
        </inertia>
      </inertial>
      <collision name="collision">
        <geometry>
          <cylinder>
            <radius>0.1</radius>
            <length>0.05</length>
          </cylinder>
        </geometry>
      </collision>
      <visual name="visual">
        <geometry>
          <cylinder>
            <radius>0.1</radius>
            <length>0.05</length>
          </cylinder>
        </geometry>
        <material>
          <ambient>0.2 0.2 0.2 1</ambient>
          <diffuse>0.2 0.2 0.2 1</diffuse>
        </material>
      </visual>
    </link>

    <!-- Caster wheel (front) -->
    <link name="caster">
      <pose>0.2 0 0.05 0 0 0</pose>
      <inertial>
        <mass>0.5</mass>
        <inertia>
          <ixx>0.001</ixx>
          <iyy>0.001</iyy>
          <izz>0.001</izz>
        </inertia>
      </inertial>
      <collision name="collision">
        <geometry>
          <sphere>
            <radius>0.05</radius>
          </sphere>
        </geometry>
        <surface>
          <friction>
            <ode>
              <mu>0.0</mu>
              <mu2>0.0</mu2>
            </ode>
          </friction>
        </surface>
      </collision>
      <visual name="visual">
        <geometry>
          <sphere>
            <radius>0.05</radius>
          </sphere>
        </geometry>
        <material>
          <ambient>0.3 0.3 0.3 1</ambient>
          <diffuse>0.3 0.3 0.3 1</diffuse>
        </material>
      </visual>
    </link>

    <!-- Joints -->
    <joint name="left_wheel_joint" type="revolute">
      <parent>base_link</parent>
      <child>left_wheel</child>
      <axis>
        <xyz>0 0 1</xyz>
      </axis>
    </joint>

    <joint name="right_wheel_joint" type="revolute">
      <parent>base_link</parent>
      <child>right_wheel</child>
      <axis>
        <xyz>0 0 1</xyz>
      </axis>
    </joint>

    <joint name="caster_joint" type="ball">
      <parent>base_link</parent>
      <child>caster</child>
    </joint>

    <!-- Differential drive plugin -->
    <plugin name="differential_drive_controller" filename="libgazebo_ros_diff_drive.so">
      <update_rate>50</update_rate>
      <left_joint>left_wheel_joint</left_joint>
      <right_joint>right_wheel_joint</right_joint>
      <wheel_separation>0.5</wheel_separation>
      <wheel_diameter>0.2</wheel_diameter>
      <max_wheel_torque>20</max_wheel_torque>
      <command_topic>person_cmd_vel</command_topic>
      <odometry_topic>person_odom</odometry_topic>
      <odometry_frame>odom</odometry_frame>
      <robot_base_frame>base_link</robot_base_frame>
      <publish_odom>true</publish_odom>
      <publish_odom_tf>false</publish_odom_tf>
      <publish_wheel_tf>false</publish_wheel_tf>
    </plugin>
  </model>
</sdf>
